nohup: ignoring input
[2024-11-03 08:13:38 +0000] [42268] [INFO] Starting gunicorn 23.0.0
[2024-11-03 08:13:38 +0000] [42268] [INFO] Listening at: unix:/home/ubuntu/qbit/website/gunicorn.sock (42268)
[2024-11-03 08:13:38 +0000] [42268] [INFO] Using worker: sync
[2024-11-03 08:13:38 +0000] [42270] [INFO] Booting worker with pid: 42270
[2024-11-03 08:16:44 +0000] [42191] [INFO] Handling signal: term
Traceback (most recent call last):
  File "/home/ubuntu/qbit/venv/lib/p[2024-11-03 08:16:44 +0000] [42023] [INFO] Shutting down: Master
  handler()
  File "/home/ubuntu/qbit/venv/lib/python3.12/site-packages/gunicorn/arbiter.py", line 256, in handle_term
    raise StopIteration
StopIteration

During handling of the above exception, another exception occurred:

Traceback (most recent call last):
  File "/home/ubuntu/qbit/venv/bin/gunicorn", line 8, in <module>
    sys.exit(run())
             ^^^^^
  File "/home/ubuntu/qbit/venv/lib/python3.12/site-packages/gunicorn/app/wsgiapp.py", line 66, in run
    WSGIApplication("%(prog)s [OPTIONS] [APP_MODULE]", prog=prog).run()
  File "/home/ubuntu/qbit/venv/lib/python3.12/site-packages/gunicorn/app/base.py", line 235, in run
    super().run()
  File "/home/ubuntu/qbit/venv/lib/python3.12/site-packages/gunicorn/app/base.py", line 71, in run
    Arbiter(self).run()
  File "/home/ubuntu/qbit/venv/lib/python3.12/site-packages/gunicorn/arbiter.py", line 226, in run
[2024-11-03 08:16:44 +0000] [42270] [INFO] Worker exiting (pid: 42270)
    self.halt()
  File "/home/ubuntu/qbit/venv/lib/python3.12/site-packages/gunicorn/arbiter.py", line 341, in halt
    self.stop()
  File "/home/ubuntu/qbit/venv/lib/python3.12/site-packages/gunicorn/arbiter.py", line 384, in stop
    sock.close_sockets(self.LISTENERS, unlink)
  File "/home/ubuntu/qbit/venv/lib/python3.12/site-packages/gunicorn/sock.py", line 212, in close_sockets
    os.unlink(sock_name)
FileNotFoundError: [Errno 2] No such file or directory: '/home/ubuntu/qbit/website/gunicorn.sock'
